<?xml version="1.0"?>
<robot name="simple_arm" xmlns:xacro="http://www.ros.org/wiki/xacro">
  <link name="base_link">
    <visual>
      <geometry>
        <box size="0.2 0.2 0.05"/>
      </geometry>
      <material name="grey">
        <color rgba="0.5 0.5 0.5 1.0"/>
      </material>
    </visual>
  </link>

  <xacro:macro name="arm_link" params="name length">
    <link name="${name}">
      <visual>
        <geometry>
          <cylinder length="${length}" radius="0.03"/>
        </geometry>
        <material name="blue">
          <color rgba="0.2 0.2 0.8 1.0"/>
        </material>
      </visual>
    </link>
  </xacro:macro>

  <xacro:arm_link name="link1" length="0.2"/>
  <xacro:arm_link name="link2" length="0.2"/>
  <xacro:arm_link name="link3" length="0.2"/>
  <xacro:arm_link name="link4" length="0.15"/>
  <xacro:arm_link name="link5" length="0.15"/>
  <xacro:arm_link name="link6" length="0.1"/>

  <joint name="joint1" type="revolute">
    <parent link="base_link"/>
    <child link="link1"/>
    <origin xyz="0 0 0.05" rpy="0 0 0"/>
    <axis xyz="0 0 1"/>
    <limit effort="50" velocity="1" lower="-3.14" upper="3.14"/>
  </joint>
  <joint name="joint2" type="revolute">
    <parent link="link1"/>
    <child link="link2"/>
    <origin xyz="0 0 0.2" rpy="0 0 0"/>
    <axis xyz="0 1 0"/>
    <limit effort="50" velocity="1" lower="-2.4" upper="2.4"/>
  </joint>
  <joint name="joint3" type="revolute">
    <parent link="link2"/>
    <child link="link3"/>
    <origin xyz="0 0 0.2" rpy="0 0 0"/>
    <axis xyz="0 1 0"/>
    <limit effort="50" velocity="1" lower="-2.4" upper="2.4"/>
  </joint>
  <joint name="joint4" type="revolute">
    <parent link="link3"/>
    <child link="link4"/>
    <origin xyz="0 0 0.2" rpy="0 0 0"/>
    <axis xyz="1 0 0"/>
    <limit effort="20" velocity="1" lower="-3.14" upper="3.14"/>
  </joint>
  <joint name="joint5" type="revolute">
    <parent link="link4"/>
    <child link="link5"/>
    <origin xyz="0 0 0.15" rpy="0 0 0"/>
    <axis xyz="0 1 0"/>
    <limit effort="20" velocity="1" lower="-3.14" upper="3.14"/>
  </joint>
  <joint name="joint6" type="revolute">
    <parent link="link5"/>
    <child link="link6"/>
    <origin xyz="0 0 0.15" rpy="0 0 0"/>
    <axis xyz="1 0 0"/>
    <limit effort="10" velocity="1" lower="-3.14" upper="3.14"/>
  </joint>

  <link name="tool0"/>
  <joint name="tool0_joint" type="fixed">
    <parent link="link6"/>
    <child link="tool0"/>
    <origin xyz="0 0 0.1" rpy="0 0 0"/>
  </joint>
</robot>
